<?xml version="1.0" encoding="UTF-8"?>
<!-- Generated by org.testng.reporters.JUnitReportReporter -->
<testsuite hostname="LAPTOP-HBBSHIBP" name="com.propine.qa.testcases.TC_FUNC_0022_VerifyErrorMessageForNullValueForSecondNumberTest" tests="1" failures="1" timestamp="26 Dec 2019 10:33:46 GMT" time="9.086" errors="0">
  <testcase name="TC_FUNC_0022_verifyErrorMessageForNullValueForSecondNumberTest" time="9.086" classname="com.propine.qa.testcases.TC_FUNC_0022_VerifyErrorMessageForNullValueForSecondNumberTest">
    <failure type="java.lang.AssertionError" message="Error Message verification for null value for Second Number - FAILED expected [Enter valid numeric or float value for Second Number] but found [NaN]">
      <![CDATA[java.lang.AssertionError: Error Message verification for null value for Second Number - FAILED expected [Enter valid numeric or float value for Second Number] but found [NaN]
	at org.testng.Assert.fail(Assert.java:94)
	at org.testng.Assert.failNotEquals(Assert.java:496)
	at org.testng.Assert.assertEquals(Assert.java:125)
	at org.testng.Assert.assertEquals(Assert.java:178)
	at com.propine.qa.testcases.TC_FUNC_0022_VerifyErrorMessageForNullValueForSecondNumberTest.TC_FUNC_0022_verifyErrorMessageForNullValueForSecondNumberTest(TC_FUNC_0022_VerifyErrorMessageForNullValueForSecondNumberTest.java:40)
	at sun.reflect.NativeMethodAccessorImpl.invoke0(Native Method)
	at sun.reflect.NativeMethodAccessorImpl.invoke(Unknown Source)
	at sun.reflect.DelegatingMethodAccessorImpl.invoke(Unknown Source)
	at java.lang.reflect.Method.invoke(Unknown Source)
	at org.testng.internal.MethodInvocationHelper.invokeMethod(MethodInvocationHelper.java:85)
	at org.testng.internal.Invoker.invokeMethod(Invoker.java:639)
	at org.testng.internal.Invoker.invokeTestMethod(Invoker.java:816)
	at org.testng.internal.Invoker.invokeTestMethods(Invoker.java:1124)
	at org.testng.internal.TestMethodWorker.invokeTestMethods(TestMethodWorker.java:125)
	at org.testng.internal.TestMethodWorker.run(TestMethodWorker.java:108)
	at org.testng.TestRunner.privateRun(TestRunner.java:774)
	at org.testng.TestRunner.run(TestRunner.java:624)
	at org.testng.SuiteRunner.runTest(SuiteRunner.java:359)
	at org.testng.SuiteRunner.runSequentially(SuiteRunner.java:354)
	at org.testng.SuiteRunner.privateRun(SuiteRunner.java:312)
	at org.testng.SuiteRunner.run(SuiteRunner.java:261)
	at org.testng.SuiteRunnerWorker.runSuite(SuiteRunnerWorker.java:52)
	at org.testng.SuiteRunnerWorker.run(SuiteRunnerWorker.java:86)
	at org.testng.TestNG.runSuitesSequentially(TestNG.java:1191)
	at org.testng.TestNG.runSuitesLocally(TestNG.java:1116)
	at org.testng.TestNG.run(TestNG.java:1024)
	at org.testng.remote.AbstractRemoteTestNG.run(AbstractRemoteTestNG.java:132)
	at org.testng.remote.RemoteTestNG.initAndRun(RemoteTestNG.java:236)
	at org.testng.remote.RemoteTestNG.main(RemoteTestNG.java:81)
]]>
    </failure>
  </testcase> <!-- TC_FUNC_0022_verifyErrorMessageForNullValueForSecondNumberTest -->
</testsuite> <!-- com.propine.qa.testcases.TC_FUNC_0022_VerifyErrorMessageForNullValueForSecondNumberTest -->
